<?xml version="1.0"?>
<robot xmlns:xacro="http://www.ros.org/wiki/xacro"> 
    <xacro:macro name="wheel_xacro" params="wheel_name xyz">
        <link name="${wheel_name}_link">
            <visual>
                <origin rpy="1.5708 0 0" xyz="${xyz}"/>
                <geometry>
                    <cylinder radius="0.05" length="0.02" />
                </geometry>
                <material name="green">
                    <color rgba="0.0 1.0 0.0 0.8"/>
                </material>
            </visual>
        </link>

        <joint name="${wheel_name}_joint" type="continuous">
            <parent link="base_link"/>
            <child link="${wheel_name}_link"/>
            <origin rpy="0 0 0" xyz="${xyz}"/>
            <axis xyz="0 1 0"/>
        </joint>
        <gazebo reference="${wheel_name}_link">
            <material>Gazebo/green</material>
            <!-- 摩擦系数（1：切向；2：法向） -->
            <mu1 value="20"/>
            <mu2 value="20"/>
            <!-- 刚度 -->
            <kp value="1000000000"/>
            <!-- 阻尼 -->
            <kd value="20"/>
        </gazebo>
    </xacro:macro>
</robot>
